{
  "test_execution_summary": {
    "execution_id": "quick_test_20251001_110616",
    "timestamp": "2025-10-01T11:06:16.749248",
    "test_type": "quick_validation",
    "environment_check": "passed",
    "basic_tests": "passed",
    "overall_status": "passed"
  },
  "environment_info": {
    "python_version": "3.12.3 (main, Aug 14 2025, 17:47:21) [GCC 13.3.0]",
    "project_root": "/root/knowledge-base-app",
    "operating_system": "posix",
    "current_directory": "/root/knowledge-base-app"
  },
  "service_status": {
    "前端服务": {
      "available": false,
      "error": "HTTPConnectionPool(host='localhost', port=3000): Max retries exceeded with url: / (Caused by NewConnectionError('<urllib3.connection.HTTPConnection object at 0x72cb97f8e390>: Failed to establish a new connection: [Errno 111] Connection refused'))",
      "url": "http://localhost:3000"
    },
    "后端服务": {
      "available": false,
      "error": "HTTPConnectionPool(host='localhost', port=5000): Max retries exceeded with url: / (Caused by NewConnectionError('<urllib3.connection.HTTPConnection object at 0x72cb97130200>: Failed to establish a new connection: [Errno 111] Connection refused'))",
      "url": "http://localhost:5000"
    }
  },
  "test_results": [
    {
      "test_id": "env_check",
      "description": "Python环境检查",
      "status": "passed",
      "steps": [
        "检查Python版本",
        "验证必要包安装"
      ],
      "expected_result": "环境配置正确",
      "actual_result": "环境检查通过"
    },
    {
      "test_id": "basic_unit_test",
      "description": "基础单元测试",
      "status": "passed",
      "steps": [
        "运行数学运算测试",
        "运行字符串操作测试",
        "运行列表操作测试"
      ],
      "expected_result": "所有基础测试通过",
      "actual_result": "基础测试通过"
    }
  ],
  "recommendations": [
    {
      "type": "service_issue",
      "priority": "medium",
      "message": "前端服务不可用，请启动相应服务"
    },
    {
      "type": "service_issue",
      "priority": "medium",
      "message": "后端服务不可用，请启动相应服务"
    }
  ]
}